[32mINFO    [0m mylogger:logger.py:83 Session started
[1m[31mERROR   [0m mylogger:logger.py:83 _callers.py::def _multicall(...)::line 39 > HTTPConnectionPool(host='google.com', port=80): Max retries exceeded with url: / (Caused by NewConnectionError('<urllib3.connection.HTTPConnection object at 0x0000019C78456D10>: Failed to establish a new connection: [Errno 11001] getaddrinfo failed'))